Workbook

Sheet 大图验证-R7130
K1: DAVINCI RX/TX
A2: case ID | B2: use case | C2: 原图size | K2: AP BUFFER SIZE | Q2: UBWC DEC | S2: IMG Resolve RX-IN | AA2: IMG Resolve RX-OUT | AI2: IMG Resolve TX-IN | AK2: IMG Resolve TX-OUT | AO2: UBWC ENC | AQ2: 输出分辨率和帧率 | AT2: 位深 | AU2: NNE 分辨率/放大倍率 | AV2: PCIe 速率 增加1.2x 余量(压缩） | AX2: 游戏/视频名称 | AY2: 定点c-model 结果 | AZ2: 网络大小以及网络版本 | BA2: 对比定点c-model效果确认结果 | BB2: 备注 | BC2: AP RX 原图大小 | BE2: 备注
C3: Color_W | D3: Color_H | E3: MV_H | F3: MV_V | G3: Depth_H | H3: Depth_V | I3: ui/人物flag_H | J3: ui/人物flag_V | K3: W-total | L3: H-total | M3: W-color-ratio | N3: W-color | O3: H-color-ratio | P3: H-color | Q3: W | R3: H | S3: Color_W | T3: Color_H | U3: MV_H | V3: MV_V | W3: Depth_H | X3: Depth_V | Y3: ui/人物flag_H | Z3: ui/人物flag_V | AA3: Color_W | AB3: Color_H | AC3: MV_H | AD3: MV_V | AE3: Depth_H | AF3: Depth_V | AG3: ui/人物flag_H | AH3: ui/人物flag_V | AI3: W | AJ3: H | AK3: W | AL3: H | AM3: PAD/ dummy-W | AN3: PAD/ dummy-H | AO3: W | AP3: H | AQ3: Color_H | AR3: Color_V | AS3: 刷新率 | AV3: PCIE RX Gbit | AW3: PCIE TX Gbit | BC3: Color_W | BD3: Color_H
A4: 1 | B4: UBWC | C4: 1888 | D4: 1624 | E4: 0 | F4: 0 | G4: 0 | H4: 0 | I4: 0 | J4: 0 | K4: =IF(MOD((C4+(CEILING(I4/32,1))+E4+G4/2),32)=0,(C4+(CEILING(I4/32,1))+E4+G4/2),_xlfn.CEILING.MATH((C4+(CEILING(I4/32,1))+E4+G4/2),32)) | L4: =IF(MOD(D4,8)=0,D4,_xlfn.CEILING.MATH(D4,8)) | M4: =CEILING(C4/32,1) | N4: =M4*32 | O4: =CEILING(D4/8,1) | P4: =O4*8 | Q4: =K4 | R4: =L4 | S4: =C4 | T4: =D4 | U4: =E4 | V4: =F4 | W4: =G4 | X4: =H4 | Y4: =I4 | Z4: =J4 | AA4: =S4 | AB4: =T4 | AC4: =U4 | AD4: =V4 | AE4: =W4 | AF4: =X4 | AG4: =Y4 | AH4: =Z4 | ... AJ4: =AB4 | AK4: =AO4 | AL4: =AP4 | AM4: =AK4-AI4 | AN4: =AL4-AJ4 | AO4: =N4 | AP4: =P4 | AQ4: 1440 | AR4: 3200 | AS4: 60 | AT4: 32 | AU4: 720P | AV4: =K4*L4*#REF!*AT4*1.2/1000/1000/1000/2 | AW4: =AQ4*AR4*AS4*AT4*1.2/1000/1000/1000/2 | AX4: 团队空间/芯片迭代/JLogic集朗/vivo算法评估/Q5VSR验证Cmodel数据/ldr_flag_1620x736_mengde_1.zip | BC4: =C4 | BD4: =D4 | BE4: UBWC ENC OUT与AP收到的原图尺寸差异-padding，由AP端处理
A5: 2 | C5: 720 | D5: 1548 | E5: 0 | F5: 0 | G5: 0 | H5: 0 | I5: 0 | J5: 0 | K5: =IF(MOD((C5+(CEILING(I5/32,1))+E5+G5/2),32)=0,(C5+(CEILING(I5/32,1))+E5+G5/2),_xlfn.CEILING.MATH((C5+(CEILING(I5/32,1))+E5+G5/2),32)) | L5: =IF(MOD(D5,8)=0,D5,_xlfn.CEILING.MATH(D5,8)) | M5: =CEILING(C5/32,1) | N5: =M5*32 | O5: =CEILING(D5/8,1) | P5: =O5*8 | Q5: =K5 | R5: =L5 | S5: =C5 | T5: =D5 | U5: =E5 | V5: =F5 | W5: =G5 | X5: =H5 | Y5: =I5 | Z5: =J5 | AA5: =S5 | AB5: =T5 | AC5: =U5 | AD5: =V5 | AE5: =W5 | AF5: =X5 | AG5: =Y5 | AH5: =Z5 | ... AJ5: =AB5 | AK5: =AO5 | AL5: =AP5 | AM5: =AK5-AI5 | AN5: =AL5-AJ5 | AO5: =N5 | AP5: =P5 | AQ5: 1440 | AR5: 3200 | AS5: 60 | AT5: 32 | AU5: 做2X | AV5: =K5*L5*#REF!*AT5*1.2/1000/1000/1000/2 | AW5: =AQ5*AR5*AS5*AT5*1.2/1000/1000/1000/2 | AX5: 团队空间/芯片迭代/Q5平板仿真素材/Q5游戏&视频验收/AISR-FPGA验收/火影忍者 | BC5: =C5 | BD5: =D5
A6: 3 | C6: 2080 | D6: 1800 | E6: 0 | F6: 0 | G6: 0 | H6: 0 | I6: 0 | J6: 0 | K6: =IF(MOD((C6+(CEILING(I6/32,1))+E6+G6/2),32)=0,(C6+(CEILING(I6/32,1))+E6+G6/2),_xlfn.CEILING.MATH((C6+(CEILING(I6/32,1))+E6+G6/2),32)) | L6: =IF(MOD(D6,8)=0,D6,_xlfn.CEILING.MATH(D6,8)) | M6: =CEILING(C6/32,1) | N6: =M6*32 | O6: =CEILING(D6/8,1) | P6: =O6*8 | Q6: =K6 | R6: =L6 | S6: =C6 | T6: =D6 | U6: =E6 | V6: =F6 | W6: =G6 | X6: =H6 | Y6: =I6 | Z6: =J6 | AA6: =S6 | AB6: =T6 | AC6: =U6 | AD6: =V6 | AE6: =W6 | AF6: =X6 | AG6: =Y6 | AH6: =Z6 | ... AJ6: =AB6 | AK6: =AO6 | AL6: =AP6 | AM6: =AK6-AI6 | AN6: =AL6-AJ6 | AO6: =N6 | AP6: =P6 | AQ6: 1440 | AR6: 3200 | AS6: 60 | AT6: 32 | AU6: 做3X | AV6: =K6*L6*#REF!*AT6*1.2/1000/1000/1000/2 | AW6: =AQ6*AR6*AS6*AT6*1.2/1000/1000/1000/2 | AX6: 团队空间/芯片迭代/Q5平板仿真素材/Q6游戏&视频验收/AISR-FPGA验收/火影忍者 | BC6: =C6 | BD6: =D6
A7: 4 | C7: 970 | D7: 2134 | E7: 0 | F7: 0 | G7: 0 | H7: 0 | I7: 0 | J7: 0 | K7: =IF(MOD((C7+(CEILING(I7/32,1))+E7+G7/2),32)=0,(C7+(CEILING(I7/32,1))+E7+G7/2),_xlfn.CEILING.MATH((C7+(CEILING(I7/32,1))+E7+G7/2),32)) | L7: =IF(MOD(D7,8)=0,D7,_xlfn.CEILING.MATH(D7,8)) | M7: =CEILING(C7/32,1) | N7: =M7*32 | O7: =CEILING(D7/8,1) | P7: =O7*8 | Q7: =K7 | R7: =L7 | S7: =C7 | T7: =D7 | U7: =E7 | V7: =F7 | W7: =G7 | X7: =H7 | Y7: =I7 | Z7: =J7 | AA7: =S7 | AB7: =T7 | AC7: =U7 | AD7: =V7 | AE7: =W7 | AF7: =X7 | AG7: =Y7 | AH7: =Z7 | ... AJ7: =AB7 | AK7: =AO7 | AL7: =AP7 | AM7: =AK7-AI7 | AN7: =AL7-AJ7 | AO7: =N7 | AP7: =P7 | AQ7: 1440 | AR7: 3200 | AS7: 60 | AT7: 32 | AU7: 做1x/1.33x | AV7: =K7*L7*#REF!*AT7*1.2/1000/1000/1000/2 | AW7: =AQ7*AR7*AS7*AT7*1.2/1000/1000/1000/2 | AX7: 团队空间/芯片迭代/Q5平板仿真素材/Q5游戏&视频验收/AISR-FPGA验收/王者荣耀 | BC7: =C7 | BD7: =D7
A8: 5 | C8: 970 | D8: 2134 | E8: 970 | F8: 2134 | G8: 970 | H8: 2134 | I8: 970 | J8: 2134 | K8: =IF(MOD((C8+(CEILING(I8/32,1))+E8+G8/2),32)=0,(C8+(CEILING(I8/32,1))+E8+G8/2),_xlfn.CEILING.MATH((C8+(CEILING(I8/32,1))+E8+G8/2),32)) | L8: =IF(MOD(D8,8)=0,D8,_xlfn.CEILING.MATH(D8,8)) | M8: =CEILING(C8/32,1) | N8: =M8*32 | O8: =CEILING(D8/8,1) | P8: =O8*8 | Q8: =K8 | R8: =L8 | S8: =C8 | T8: =D8 | U8: =E8 | V8: =F8 | W8: =G8 | X8: =H8 | Y8: =I8 | Z8: =J8 | AA8: =S8 | AB8: =T8 | AC8: =U8 | AD8: =V8 | AE8: =W8 | AF8: =X8 | AG8: =Y8 | AH8: =Z8 | ... AJ8: =AB8 | AK8: =AO8 | AL8: =AP8 | AM8: =AK8-AI8 | AN8: =AL8-AJ8 | AO8: =N8 | AP8: =P8 | AQ8: 1440 | AR8: 3200 | AS8: 60 | AT8: 32 | AU8: 做1x/1.34x | AV8: =K8*L8*#REF!*AT8*1.2/1000/1000/1000/2 | AW8: =AQ8*AR8*AS8*AT8*1.2/1000/1000/1000/2 | AX8: 团队空间/芯片迭代/Q5平板仿真素材/Q6游戏&视频验收/AISR-FPGA验收/王者荣耀 | BC8: =C8 | BD8: =D8
M10: =C4/32 | Q10: =1888/16 | R10: =1624/4

Sheet UBWC寄存器配置
A1: UBWC ENC/DEC 寄存器配置参考
A2: 使用规则 | B2: REG_OTF_CFG1 / DEC OTF timing 的 active 宽高应配置实际 OTF 流或输出 active 区域；metadata/tile layout 使用 stored/layout 对齐尺寸。
A3: ENC | B3: 若 OTF 输入流已经包含 padding，J 列选择“是”，ENC REG_OTF_CFG1 使用 padding W/H；REG_META_ACTIVE_SIZE 仍使用原图 active W/H。
A4: DEC | B4: DEC 输出 OTF 的 h_act/v_act 使用原图 active W/H，不使用 stored_h/padding_h；stored/layout 只影响 META_CFG0、pitch 和地址 layout。
A5: 地址寄存器 | B5: 每帧地址仍按实际 buffer base 写 META_Y、TILE_Y、META_UV、TILE_UV 的 low/high；本表只计算静态/几何/timing 寄存器。
A6: 固定配置参考 | B6: ENC CI_CFG0=0x00000701；DEC TILE_CFG2=0x00000001；DEC VIVO_CFG=0x00000001；IRQ enable 需要时写 bit0=1，start 每帧写 bit5=1。
A8: case ID | B8: use case | C8: 原图_W | D8: 原图_H | E8: 格式 | F8: format_code | G8: tile_w | H8: tile_h | I8: bpp(Y/RGBA) | J8: OTF使用padding? | K8: 原表padding_W | L8: 原表padding_H | M8: ENC_OTF_W | N8: ENC_OTF_H | O8: active_W | P8: active_H | Q8: stored_W | R8: stored_H | S8: Y_tile_cols | T8: Y_tile_rows | U8: UV_tile_cols | V8: meta_pitch | W8: tile_pitch | X8: ENC 0x00C TILE_CFG1 | Y8: ENC 0x020 OTF_CFG0 | Z8: ENC 0x024 OTF_CFG1 | AA8: ENC 0x028 OTF_CFG2 | AB8: ENC 0x02C OTF_CFG3 | AC8: ENC 0x050 META_ACTIVE_SIZE | AD8: ENC 0x054 META_PITCH | AE8: DEC 0x00C TILE_CFG1 | AF8: DEC 0x018 OTF_CFG0 | AG8: DEC 0x01C OTF_CFG1 | AH8: DEC 0x020 OTF_CFG2 | AI8: DEC 0x024 OTF_CFG3 | AJ8: DEC 0x028 OTF_CFG4 | AK8: DEC 0x02C META_CFG0 | AL8: ENC固定0x008 TILE_CFG0 | AM8: DEC固定0x008 TILE_CFG0 | AN8: 备注 | AO8: 单case sheet
A9: ='大图验证-R7130'!A4 | B9: ='大图验证-R7130'!B4 | C9: ='大图验证-R7130'!C4 | D9: ='大图验证-R7130'!D4 | E9: YUV420_8/NV12 | F9: =IF(E9="RGBA8888",0,IF(E9="RGBA1010102",1,IF(E9="YUV420_10/P010",3,2))) | G9: =IF(LEFT(E9,4)="RGBA",16,32) | H9: =IF(OR(E9="RGBA8888",E9="RGBA1010102",E9="YUV420_10/P010"),4,8) | I9: =IF(LEFT(E9,4)="RGBA",4,IF(E9="YUV420_10/P010",2,1)) | J9: 否 | K9: =IF('大图验证-R7130'!AO4<>"",'大图验证-R7130'!AO4,IF('大图验证-R7130'!N4<>"",'大图验证-R7130'!N4,CEILING(C9,G9*4))) | L9: =IF('大图验证-R7130'!AP4<>"",'大图验证-R7130'!AP4,IF('大图验证-R7130'!P4<>"",'大图验证-R7130'!P4,CEILING(D9,H9*4))) | M9: =IF(J9="是",MAX(K9,CEILING(C9,G9*4)),C9) | N9: =IF(J9="是",MAX(L9,CEILING(D9,H9*4)),D9) | O9: =C9 | P9: =D9 | Q9: =MAX(CEILING(O9,G9*4),IF(K9="",0,K9)) | R9: =MAX(CEILING(P9,H9*4),IF(L9="",0,L9)) | S9: =Q9/G9 | T9: =R9/H9 | U9: =IF(LEFT(E9,4)="RGBA",0,S9) | V9: =CEILING(S9,64) | W9: =Q9*I9/16 | X9: ="0x"&UPPER(RIGHT("00000000"&DEC2HEX(W9*65536+IF(LEFT(E9,4)="RGBA",1,0)),8)) | Y9: ="0x"&UPPER(RIGHT("00000000"&DEC2HEX(F9),8)) | Z9: ="0x"&UPPER(RIGHT("00000000"&DEC2HEX(N9*65536+M9),8)) | AA9: ="0x"&UPPER(RIGHT("00000000"&DEC2HEX(H9*65536+G9),8)) | AB9: ="0x"&UPPER(RIGHT("00000000"&DEC2HEX(U9*65536+S9),8)) | AC9: ="0x"&UPPER(RIGHT("00000000"&DEC2HEX(P9*65536+O9),8)) | AD9: ="0x"&UPPER(RIGHT("00000000"&DEC2HEX(V9),8)) | AE9: ="0x"&UPPER(RIGHT("00000000"&DEC2HEX(W9),8)) | AF9: ="0x"&UPPER(RIGHT("00000000"&DEC2HEX(F9*65536+O9),8)) | AG9: ="0x"&UPPER(RIGHT("00000000"&DEC2HEX(O9),8)) | AH9: ="0x"&UPPER(RIGHT("00000000"&DEC2HEX(O9*65536),8)) | AI9: ="0x"&UPPER(RIGHT("00000000"&DEC2HEX(P9),8)) | AJ9: ="0x"&UPPER(RIGHT("00000000"&DEC2HEX(P9*65536),8)) | AK9: ="0x"&UPPER(RIGHT("00000000"&DEC2HEX(T9*65536+S9),8)) | AL9: ="0x"&UPPER(RIGHT("00000000"&DEC2HEX(1+4+8+16*256+65536),8)) | AM9: ="0x"&UPPER(RIGHT("00000000"&DEC2HEX(2+4+16*16+512+IF(LEFT(E9,4)="RGBA",1024,0)),8)) | AN9: =IF(J9="是","ENC OTF_CFG1 用 padding W/H；META_ACTIVE_SIZE 仍用原图 active W/H。DEC h_act/v_act 固定用原图 W/H。","ENC/DEC active 都用原图 W/H；stored/layout 只用于 tile/meta/pitch。") | AO9: case01_1888x1624
A10: ='大图验证-R7130'!A5 | B10: ='大图验证-R7130'!B5 | C10: ='大图验证-R7130'!C5 | D10: ='大图验证-R7130'!D5 | E10: YUV420_8/NV12 | F10: =IF(E10="RGBA8888",0,IF(E10="RGBA1010102",1,IF(E10="YUV420_10/P010",3,2))) | G10: =IF(LEFT(E10,4)="RGBA",16,32) | H10: =IF(OR(E10="RGBA8888",E10="RGBA1010102",E10="YUV420_10/P010"),4,8) | I10: =IF(LEFT(E10,4)="RGBA",4,IF(E10="YUV420_10/P010",2,1)) | J10: 否 | K10: =IF('大图验证-R7130'!AO5<>"",'大图验证-R7130'!AO5,IF('大图验证-R7130'!N5<>"",'大图验证-R7130'!N5,CEILING(C10,G10*4))) | L10: =IF('大图验证-R7130'!AP5<>"",'大图验证-R7130'!AP5,IF('大图验证-R7130'!P5<>"",'大图验证-R7130'!P5,CEILING(D10,H10*4))) | M10: =IF(J10="是",MAX(K10,CEILING(C10,G10*4)),C10) | N10: =IF(J10="是",MAX(L10,CEILING(D10,H10*4)),D10) | O10: =C10 | P10: =D10 | Q10: =MAX(CEILING(O10,G10*4),IF(K10="",0,K10)) | R10: =MAX(CEILING(P10,H10*4),IF(L10="",0,L10)) | S10: =Q10/G10 | T10: =R10/H10 | U10: =IF(LEFT(E10,4)="RGBA",0,S10) | V10: =CEILING(S10,64) | W10: =Q10*I10/16 | X10: ="0x"&UPPER(RIGHT("00000000"&DEC2HEX(W10*65536+IF(LEFT(E10,4)="RGBA",1,0)),8)) | Y10: ="0x"&UPPER(RIGHT("00000000"&DEC2HEX(F10),8)) | Z10: ="0x"&UPPER(RIGHT("00000000"&DEC2HEX(N10*65536+M10),8)) | AA10: ="0x"&UPPER(RIGHT("00000000"&DEC2HEX(H10*65536+G10),8)) | AB10: ="0x"&UPPER(RIGHT("00000000"&DEC2HEX(U10*65536+S10),8)) | AC10: ="0x"&UPPER(RIGHT("00000000"&DEC2HEX(P10*65536+O10),8)) | AD10: ="0x"&UPPER(RIGHT("00000000"&DEC2HEX(V10),8)) | AE10: ="0x"&UPPER(RIGHT("00000000"&DEC2HEX(W10),8)) | AF10: ="0x"&UPPER(RIGHT("00000000"&DEC2HEX(F10*65536+O10),8)) | AG10: ="0x"&UPPER(RIGHT("00000000"&DEC2HEX(O10),8)) | AH10: ="0x"&UPPER(RIGHT("00000000"&DEC2HEX(O10*65536),8)) | AI10: ="0x"&UPPER(RIGHT("00000000"&DEC2HEX(P10),8)) | AJ10: ="0x"&UPPER(RIGHT("00000000"&DEC2HEX(P10*65536),8)) | AK10: ="0x"&UPPER(RIGHT("00000000"&DEC2HEX(T10*65536+S10),8)) | AL10: ="0x"&UPPER(RIGHT("00000000"&DEC2HEX(1+4+8+16*256+65536),8)) | AM10: ="0x"&UPPER(RIGHT("00000000"&DEC2HEX(2+4+16*16+512+IF(LEFT(E10,4)="RGBA",1024,0)),8)) | AN10: =IF(J10="是","ENC OTF_CFG1 用 padding W/H；META_ACTIVE_SIZE 仍用原图 active W/H。DEC h_act/v_act 固定用原图 W/H。","ENC/DEC active 都用原图 W/H；stored/layout 只用于 tile/meta/pitch。") | AO10: case02_720x1548
A11: ='大图验证-R7130'!A6 | B11: ='大图验证-R7130'!B6 | C11: ='大图验证-R7130'!C6 | D11: ='大图验证-R7130'!D6 | E11: YUV420_8/NV12 | F11: =IF(E11="RGBA8888",0,IF(E11="RGBA1010102",1,IF(E11="YUV420_10/P010",3,2))) | G11: =IF(LEFT(E11,4)="RGBA",16,32) | H11: =IF(OR(E11="RGBA8888",E11="RGBA1010102",E11="YUV420_10/P010"),4,8) | I11: =IF(LEFT(E11,4)="RGBA",4,IF(E11="YUV420_10/P010",2,1)) | J11: 否 | K11: =IF('大图验证-R7130'!AO6<>"",'大图验证-R7130'!AO6,IF('大图验证-R7130'!N6<>"",'大图验证-R7130'!N6,CEILING(C11,G11*4))) | L11: =IF('大图验证-R7130'!AP6<>"",'大图验证-R7130'!AP6,IF('大图验证-R7130'!P6<>"",'大图验证-R7130'!P6,CEILING(D11,H11*4))) | M11: =IF(J11="是",MAX(K11,CEILING(C11,G11*4)),C11) | N11: =IF(J11="是",MAX(L11,CEILING(D11,H11*4)),D11) | O11: =C11 | P11: =D11 | Q11: =MAX(CEILING(O11,G11*4),IF(K11="",0,K11)) | R11: =MAX(CEILING(P11,H11*4),IF(L11="",0,L11)) | S11: =Q11/G11 | T11: =R11/H11 | U11: =IF(LEFT(E11,4)="RGBA",0,S11) | V11: =CEILING(S11,64) | W11: =Q11*I11/16 | X11: ="0x"&UPPER(RIGHT("00000000"&DEC2HEX(W11*65536+IF(LEFT(E11,4)="RGBA",1,0)),8)) | Y11: ="0x"&UPPER(RIGHT("00000000"&DEC2HEX(F11),8)) | Z11: ="0x"&UPPER(RIGHT("00000000"&DEC2HEX(N11*65536+M11),8)) | AA11: ="0x"&UPPER(RIGHT("00000000"&DEC2HEX(H11*65536+G11),8)) | AB11: ="0x"&UPPER(RIGHT("00000000"&DEC2HEX(U11*65536+S11),8)) | AC11: ="0x"&UPPER(RIGHT("00000000"&DEC2HEX(P11*65536+O11),8)) | AD11: ="0x"&UPPER(RIGHT("00000000"&DEC2HEX(V11),8)) | AE11: ="0x"&UPPER(RIGHT("00000000"&DEC2HEX(W11),8)) | AF11: ="0x"&UPPER(RIGHT("00000000"&DEC2HEX(F11*65536+O11),8)) | AG11: ="0x"&UPPER(RIGHT("00000000"&DEC2HEX(O11),8)) | AH11: ="0x"&UPPER(RIGHT("00000000"&DEC2HEX(O11*65536),8)) | AI11: ="0x"&UPPER(RIGHT("00000000"&DEC2HEX(P11),8)) | AJ11: ="0x"&UPPER(RIGHT("00000000"&DEC2HEX(P11*65536),8)) | AK11: ="0x"&UPPER(RIGHT("00000000"&DEC2HEX(T11*65536+S11),8)) | AL11: ="0x"&UPPER(RIGHT("00000000"&DEC2HEX(1+4+8+16*256+65536),8)) | AM11: ="0x"&UPPER(RIGHT("00000000"&DEC2HEX(2+4+16*16+512+IF(LEFT(E11,4)="RGBA",1024,0)),8)) | AN11: =IF(J11="是","ENC OTF_CFG1 用 padding W/H；META_ACTIVE_SIZE 仍用原图 active W/H。DEC h_act/v_act 固定用原图 W/H。","ENC/DEC active 都用原图 W/H；stored/layout 只用于 tile/meta/pitch。") | AO11: case03_2080x1800
A12: ='大图验证-R7130'!A7 | B12: ='大图验证-R7130'!B7 | C12: ='大图验证-R7130'!C7 | D12: ='大图验证-R7130'!D7 | E12: YUV420_8/NV12 | F12: =IF(E12="RGBA8888",0,IF(E12="RGBA1010102",1,IF(E12="YUV420_10/P010",3,2))) | G12: =IF(LEFT(E12,4)="RGBA",16,32) | H12: =IF(OR(E12="RGBA8888",E12="RGBA1010102",E12="YUV420_10/P010"),4,8) | I12: =IF(LEFT(E12,4)="RGBA",4,IF(E12="YUV420_10/P010",2,1)) | J12: 否 | K12: =IF('大图验证-R7130'!AO7<>"",'大图验证-R7130'!AO7,IF('大图验证-R7130'!N7<>"",'大图验证-R7130'!N7,CEILING(C12,G12*4))) | L12: =IF('大图验证-R7130'!AP7<>"",'大图验证-R7130'!AP7,IF('大图验证-R7130'!P7<>"",'大图验证-R7130'!P7,CEILING(D12,H12*4))) | M12: =IF(J12="是",MAX(K12,CEILING(C12,G12*4)),C12) | N12: =IF(J12="是",MAX(L12,CEILING(D12,H12*4)),D12) | O12: =C12 | P12: =D12 | Q12: =MAX(CEILING(O12,G12*4),IF(K12="",0,K12)) | R12: =MAX(CEILING(P12,H12*4),IF(L12="",0,L12)) | S12: =Q12/G12 | T12: =R12/H12 | U12: =IF(LEFT(E12,4)="RGBA",0,S12) | V12: =CEILING(S12,64) | W12: =Q12*I12/16 | X12: ="0x"&UPPER(RIGHT("00000000"&DEC2HEX(W12*65536+IF(LEFT(E12,4)="RGBA",1,0)),8)) | Y12: ="0x"&UPPER(RIGHT("00000000"&DEC2HEX(F12),8)) | Z12: ="0x"&UPPER(RIGHT("00000000"&DEC2HEX(N12*65536+M12),8)) | AA12: ="0x"&UPPER(RIGHT("00000000"&DEC2HEX(H12*65536+G12),8)) | AB12: ="0x"&UPPER(RIGHT("00000000"&DEC2HEX(U12*65536+S12),8)) | AC12: ="0x"&UPPER(RIGHT("00000000"&DEC2HEX(P12*65536+O12),8)) | AD12: ="0x"&UPPER(RIGHT("00000000"&DEC2HEX(V12),8)) | AE12: ="0x"&UPPER(RIGHT("00000000"&DEC2HEX(W12),8)) | AF12: ="0x"&UPPER(RIGHT("00000000"&DEC2HEX(F12*65536+O12),8)) | AG12: ="0x"&UPPER(RIGHT("00000000"&DEC2HEX(O12),8)) | AH12: ="0x"&UPPER(RIGHT("00000000"&DEC2HEX(O12*65536),8)) | AI12: ="0x"&UPPER(RIGHT("00000000"&DEC2HEX(P12),8)) | AJ12: ="0x"&UPPER(RIGHT("00000000"&DEC2HEX(P12*65536),8)) | AK12: ="0x"&UPPER(RIGHT("00000000"&DEC2HEX(T12*65536+S12),8)) | AL12: ="0x"&UPPER(RIGHT("00000000"&DEC2HEX(1+4+8+16*256+65536),8)) | AM12: ="0x"&UPPER(RIGHT("00000000"&DEC2HEX(2+4+16*16+512+IF(LEFT(E12,4)="RGBA",1024,0)),8)) | AN12: =IF(J12="是","ENC OTF_CFG1 用 padding W/H；META_ACTIVE_SIZE 仍用原图 active W/H。DEC h_act/v_act 固定用原图 W/H。","ENC/DEC active 都用原图 W/H；stored/layout 只用于 tile/meta/pitch。") | AO12: case04_970x2134
A13: ='大图验证-R7130'!A8 | B13: ='大图验证-R7130'!B8 | C13: ='大图验证-R7130'!C8 | D13: ='大图验证-R7130'!D8 | E13: YUV420_8/NV12 | F13: =IF(E13="RGBA8888",0,IF(E13="RGBA1010102",1,IF(E13="YUV420_10/P010",3,2))) | G13: =IF(LEFT(E13,4)="RGBA",16,32) | H13: =IF(OR(E13="RGBA8888",E13="RGBA1010102",E13="YUV420_10/P010"),4,8) | I13: =IF(LEFT(E13,4)="RGBA",4,IF(E13="YUV420_10/P010",2,1)) | J13: 否 | K13: =IF('大图验证-R7130'!AO8<>"",'大图验证-R7130'!AO8,IF('大图验证-R7130'!N8<>"",'大图验证-R7130'!N8,CEILING(C13,G13*4))) | L13: =IF('大图验证-R7130'!AP8<>"",'大图验证-R7130'!AP8,IF('大图验证-R7130'!P8<>"",'大图验证-R7130'!P8,CEILING(D13,H13*4))) | M13: =IF(J13="是",MAX(K13,CEILING(C13,G13*4)),C13) | N13: =IF(J13="是",MAX(L13,CEILING(D13,H13*4)),D13) | O13: =C13 | P13: =D13 | Q13: =MAX(CEILING(O13,G13*4),IF(K13="",0,K13)) | R13: =MAX(CEILING(P13,H13*4),IF(L13="",0,L13)) | S13: =Q13/G13 | T13: =R13/H13 | U13: =IF(LEFT(E13,4)="RGBA",0,S13) | V13: =CEILING(S13,64) | W13: =Q13*I13/16 | X13: ="0x"&UPPER(RIGHT("00000000"&DEC2HEX(W13*65536+IF(LEFT(E13,4)="RGBA",1,0)),8)) | Y13: ="0x"&UPPER(RIGHT("00000000"&DEC2HEX(F13),8)) | Z13: ="0x"&UPPER(RIGHT("00000000"&DEC2HEX(N13*65536+M13),8)) | AA13: ="0x"&UPPER(RIGHT("00000000"&DEC2HEX(H13*65536+G13),8)) | AB13: ="0x"&UPPER(RIGHT("00000000"&DEC2HEX(U13*65536+S13),8)) | AC13: ="0x"&UPPER(RIGHT("00000000"&DEC2HEX(P13*65536+O13),8)) | AD13: ="0x"&UPPER(RIGHT("00000000"&DEC2HEX(V13),8)) | AE13: ="0x"&UPPER(RIGHT("00000000"&DEC2HEX(W13),8)) | AF13: ="0x"&UPPER(RIGHT("00000000"&DEC2HEX(F13*65536+O13),8)) | AG13: ="0x"&UPPER(RIGHT("00000000"&DEC2HEX(O13),8)) | AH13: ="0x"&UPPER(RIGHT("00000000"&DEC2HEX(O13*65536),8)) | AI13: ="0x"&UPPER(RIGHT("00000000"&DEC2HEX(P13),8)) | AJ13: ="0x"&UPPER(RIGHT("00000000"&DEC2HEX(P13*65536),8)) | AK13: ="0x"&UPPER(RIGHT("00000000"&DEC2HEX(T13*65536+S13),8)) | AL13: ="0x"&UPPER(RIGHT("00000000"&DEC2HEX(1+4+8+16*256+65536),8)) | AM13: ="0x"&UPPER(RIGHT("00000000"&DEC2HEX(2+4+16*16+512+IF(LEFT(E13,4)="RGBA",1024,0)),8)) | AN13: =IF(J13="是","ENC OTF_CFG1 用 padding W/H；META_ACTIVE_SIZE 仍用原图 active W/H。DEC h_act/v_act 固定用原图 W/H。","ENC/DEC active 都用原图 W/H；stored/layout 只用于 tile/meta/pitch。") | AO13: case05_970x2134
A16: 每帧地址寄存器写入顺序
A17: 模块 | B17: 寄存器地址 | C17: 寄存器名 | D17: 说明
A18: ENC | B18: 0x030/0x034 | C18: REG_META_BASE_Y_LO/HI | D18: Y/RGBA metadata base low/high
A19: ENC | B19: 0x038/0x03C | C19: REG_TILE_BASE_Y_LO/HI | D19: Y/RGBA tile data base low/high
A20: ENC | B20: 0x040/0x044 | C20: REG_META_BASE_UV_LO/HI | D20: UV metadata base low/high；RGBA 写 0
A21: ENC | B21: 0x048/0x04C | C21: REG_TILE_BASE_UV_LO/HI | D21: UV tile data base low/high；写 0x04C 后提交地址组
A22: ENC | B22: 0x060 bit5 | C22: START | D22: 地址组写完后每帧写 start token
A23: DEC | B23: 0x030/0x034 | C23: REG_META_BASE_Y_LO/HI | D23: RGBA/Y metadata base low/high
A24: DEC | B24: 0x038/0x03C | C24: REG_TILE_BASE_Y_LO/HI | D24: RGBA/Y tile data base low/high
A25: DEC | B25: 0x040/0x044 | C25: REG_META_BASE_UV_LO/HI | D25: UV metadata base low/high；RGBA 不使用
A26: DEC | B26: 0x048/0x04C | C26: REG_TILE_BASE_UV_LO/HI | D26: UV tile data base low/high；RGBA 不使用
A27: DEC | B27: 0x060 bit5 | C27: START | D27: 完整地址组和 start token 都有效后启动 decode

Sheet case01_1888x1624
A1: UBWC case01 寄存器配置
A2: 说明 | B2: 本页所有关键值引用总览页；如需改格式或是否使用 padding，请优先修改总览页对应行。Excel 打开后会自动重算公式。
A3: 返回总览 | B3: UBWC寄存器配置
A5: 1. 输入参数与派生尺寸
A6: 字段 | B6: 值 | C6: 说明
A7: Case ID | B7: ='UBWC寄存器配置'!A9 | C7: 原始 case 编号
A8: Use case | B8: ='UBWC寄存器配置'!B9 | C8: 原表用途
A9: 格式 | B9: ='UBWC寄存器配置'!E9 | C9: 当前配置格式；总览页可下拉修改
A10: format_code | B10: ='UBWC寄存器配置'!F9 | C10: 写入 OTF/format 字段的格式码
A11: 原图 W/H | B11: ='UBWC寄存器配置'!C9&" x "&'UBWC寄存器配置'!D9 | C11: 真实有效图像尺寸
A12: active W/H | B12: ='UBWC寄存器配置'!O9&" x "&'UBWC寄存器配置'!P9 | C12: ENC META_ACTIVE_SIZE / DEC OTF active 使用
A13: stored W/H | B13: ='UBWC寄存器配置'!Q9&" x "&'UBWC寄存器配置'!R9 | C13: UBWC layout/tile/meta 使用的对齐后尺寸
A14: ENC OTF W/H | B14: ='UBWC寄存器配置'!M9&" x "&'UBWC寄存器配置'!N9 | C14: ENC 输入流尺寸；默认不使用 padding
A15: tile W/H | B15: ='UBWC寄存器配置'!G9&" x "&'UBWC寄存器配置'!H9 | C15: 由格式决定
A16: Y tile cols/rows | B16: ='UBWC寄存器配置'!S9&" x "&'UBWC寄存器配置'!T9 | C16: Y/RGBA plane tile 数
A17: UV tile cols | B17: ='UBWC寄存器配置'!U9 | C17: RGBA 为 0；YUV420 与 Y tile cols 相同
A18: meta pitch | B18: ='UBWC寄存器配置'!V9 | C18: metadata pitch，按 64B 对齐
A19: tile pitch | B19: ='UBWC寄存器配置'!W9 | C19: 压缩 tile plane pitch 配置值
A21: 2. ENC 静态寄存器配置
A22: 步骤 | B22: 地址 | C22: 寄存器 | D22: 写入值 | E22: 配置频率 | F22: 说明
A23: 1 | B23: 0x008 | C23: REG_TILE_CFG0 | D23: ='UBWC寄存器配置'!AL9 | E23: 图像格式变化时配置 | F23: bank swizzle/bank spread 等固定建议配置
A24: 2 | B24: 0x00C | C24: REG_TILE_CFG1 | D24: ='UBWC寄存器配置'!X9 | E24: 图像格式/尺寸变化时配置 | F24: tile_pitch 和 RGBA/YUV plane 类型相关配置
A25: 3 | B25: 0x010 | C25: REG_ENC_CI_CFG0 | D25: 0x00000701 | E25: 图像格式变化时配置 | F25: CI input type=1(tiled data)，CI alen 默认 7
A26: 4 | B26: 0x020 | C26: REG_OTF_CFG0 | D26: ='UBWC寄存器配置'!Y9 | E26: 图像格式变化时配置 | F26: ENC OTF 输入 format
A27: 5 | B27: 0x024 | C27: REG_OTF_CFG1 | D27: ='UBWC寄存器配置'!Z9 | E27: 图像尺寸变化时配置 | F27: ENC OTF 输入 width/height；若总览选择 padding，则这里用 padding W/H
A28: 6 | B28: 0x028 | C28: REG_OTF_CFG2 | D28: ='UBWC寄存器配置'!AA9 | E28: 图像格式变化时配置 | F28: tile_w/tile_h
A29: 7 | B29: 0x02C | C29: REG_OTF_CFG3 | D29: ='UBWC寄存器配置'!AB9 | E29: 图像尺寸变化时配置 | F29: Y/UV tile cols；RGBA 的 UV 侧为 0
A30: 8 | B30: 0x050 | C30: REG_META_ACTIVE_SIZE | D30: ='UBWC寄存器配置'!AC9 | E30: 图像有效尺寸变化时配置 | F30: 真实 active W/H，不使用 padding W/H
A31: 9 | B31: 0x054 | C31: REG_META_PITCH | D31: ='UBWC寄存器配置'!AD9 | E31: 图像尺寸变化时配置 | F31: metadata plane pitch
A32: 10 | B32: 0x060 | C32: REG_IRQ_CTRL | D32: 0x00000001 | E32: 上电后或中断策略变化时配置 | F32: bit0 irq_enable=1；bit6 可按需配置 vsync reset enable
A34: 3. ENC 每帧地址与启动
A35: 步骤 | B35: 地址 | C35: 寄存器/字段 | D35: 写入值 | E35: 配置频率 | F35: 说明
A36: 1 | B36: 0x030 | C36: REG_META_BASE_Y_LO | D36: <meta_y_base[31:0]> | E36: 每帧配置 | F36: 压缩后 Y/RGBA metadata 存储基地址低 32 bit
A37: 2 | B37: 0x034 | C37: REG_META_BASE_Y_HI | D37: <meta_y_base[63:32]> | E37: 每帧配置 | F37: 压缩后 Y/RGBA metadata 存储基地址高 32 bit
A38: 3 | B38: 0x038 | C38: REG_TILE_BASE_Y_LO | D38: <tile_y_base[31:0]> | E38: 每帧配置 | F38: 压缩后 Y/RGBA tile 数据存储基地址低 32 bit
A39: 4 | B39: 0x03C | C39: REG_TILE_BASE_Y_HI | D39: <tile_y_base[63:32]> | E39: 每帧配置 | F39: 压缩后 Y/RGBA tile 数据存储基地址高 32 bit
A40: 5 | B40: 0x040 | C40: REG_META_BASE_UV_LO | D40: <meta_uv_base[31:0]> | E40: 每帧配置 | F40: UV metadata 存储基地址低 32 bit；RGBA 可写 0
A41: 6 | B41: 0x044 | C41: REG_META_BASE_UV_HI | D41: <meta_uv_base[63:32]> | E41: 每帧配置 | F41: UV metadata 存储基地址高 32 bit；RGBA 可写 0
A42: 7 | B42: 0x048 | C42: REG_TILE_BASE_UV_LO | D42: <tile_uv_base[31:0]> | E42: 每帧配置 | F42: UV tile 数据存储基地址低 32 bit；RGBA 可写 0
A43: 8 | B43: 0x04C | C43: REG_TILE_BASE_UV_HI | D43: <tile_uv_base[63:32]> | E43: 每帧配置 | F43: UV tile 数据存储基地址高 32 bit；写该 high word 后提交地址组
...

Sheet case02_720x1548
A1: UBWC case02 寄存器配置
A2: 说明 | B2: 本页所有关键值引用总览页；如需改格式或是否使用 padding，请优先修改总览页对应行。Excel 打开后会自动重算公式。
A3: 返回总览 | B3: UBWC寄存器配置
A5: 1. 输入参数与派生尺寸
A6: 字段 | B6: 值 | C6: 说明
A7: Case ID | B7: ='UBWC寄存器配置'!A10 | C7: 原始 case 编号
A8: Use case | B8: ='UBWC寄存器配置'!B10 | C8: 原表用途
A9: 格式 | B9: ='UBWC寄存器配置'!E10 | C9: 当前配置格式；总览页可下拉修改
A10: format_code | B10: ='UBWC寄存器配置'!F10 | C10: 写入 OTF/format 字段的格式码
A11: 原图 W/H | B11: ='UBWC寄存器配置'!C10&" x "&'UBWC寄存器配置'!D10 | C11: 真实有效图像尺寸
A12: active W/H | B12: ='UBWC寄存器配置'!O10&" x "&'UBWC寄存器配置'!P10 | C12: ENC META_ACTIVE_SIZE / DEC OTF active 使用
A13: stored W/H | B13: ='UBWC寄存器配置'!Q10&" x "&'UBWC寄存器配置'!R10 | C13: UBWC layout/tile/meta 使用的对齐后尺寸
A14: ENC OTF W/H | B14: ='UBWC寄存器配置'!M10&" x "&'UBWC寄存器配置'!N10 | C14: ENC 输入流尺寸；默认不使用 padding
A15: tile W/H | B15: ='UBWC寄存器配置'!G10&" x "&'UBWC寄存器配置'!H10 | C15: 由格式决定
A16: Y tile cols/rows | B16: ='UBWC寄存器配置'!S10&" x "&'UBWC寄存器配置'!T10 | C16: Y/RGBA plane tile 数
A17: UV tile cols | B17: ='UBWC寄存器配置'!U10 | C17: RGBA 为 0；YUV420 与 Y tile cols 相同
A18: meta pitch | B18: ='UBWC寄存器配置'!V10 | C18: metadata pitch，按 64B 对齐
A19: tile pitch | B19: ='UBWC寄存器配置'!W10 | C19: 压缩 tile plane pitch 配置值
A21: 2. ENC 静态寄存器配置
A22: 步骤 | B22: 地址 | C22: 寄存器 | D22: 写入值 | E22: 配置频率 | F22: 说明
A23: 1 | B23: 0x008 | C23: REG_TILE_CFG0 | D23: ='UBWC寄存器配置'!AL10 | E23: 图像格式变化时配置 | F23: bank swizzle/bank spread 等固定建议配置
A24: 2 | B24: 0x00C | C24: REG_TILE_CFG1 | D24: ='UBWC寄存器配置'!X10 | E24: 图像格式/尺寸变化时配置 | F24: tile_pitch 和 RGBA/YUV plane 类型相关配置
A25: 3 | B25: 0x010 | C25: REG_ENC_CI_CFG0 | D25: 0x00000701 | E25: 图像格式变化时配置 | F25: CI input type=1(tiled data)，CI alen 默认 7
A26: 4 | B26: 0x020 | C26: REG_OTF_CFG0 | D26: ='UBWC寄存器配置'!Y10 | E26: 图像格式变化时配置 | F26: ENC OTF 输入 format
A27: 5 | B27: 0x024 | C27: REG_OTF_CFG1 | D27: ='UBWC寄存器配置'!Z10 | E27: 图像尺寸变化时配置 | F27: ENC OTF 输入 width/height；若总览选择 padding，则这里用 padding W/H
A28: 6 | B28: 0x028 | C28: REG_OTF_CFG2 | D28: ='UBWC寄存器配置'!AA10 | E28: 图像格式变化时配置 | F28: tile_w/tile_h
A29: 7 | B29: 0x02C | C29: REG_OTF_CFG3 | D29: ='UBWC寄存器配置'!AB10 | E29: 图像尺寸变化时配置 | F29: Y/UV tile cols；RGBA 的 UV 侧为 0
A30: 8 | B30: 0x050 | C30: REG_META_ACTIVE_SIZE | D30: ='UBWC寄存器配置'!AC10 | E30: 图像有效尺寸变化时配置 | F30: 真实 active W/H，不使用 padding W/H
A31: 9 | B31: 0x054 | C31: REG_META_PITCH | D31: ='UBWC寄存器配置'!AD10 | E31: 图像尺寸变化时配置 | F31: metadata plane pitch
A32: 10 | B32: 0x060 | C32: REG_IRQ_CTRL | D32: 0x00000001 | E32: 上电后或中断策略变化时配置 | F32: bit0 irq_enable=1；bit6 可按需配置 vsync reset enable
A34: 3. ENC 每帧地址与启动
A35: 步骤 | B35: 地址 | C35: 寄存器/字段 | D35: 写入值 | E35: 配置频率 | F35: 说明
A36: 1 | B36: 0x030 | C36: REG_META_BASE_Y_LO | D36: <meta_y_base[31:0]> | E36: 每帧配置 | F36: 压缩后 Y/RGBA metadata 存储基地址低 32 bit
A37: 2 | B37: 0x034 | C37: REG_META_BASE_Y_HI | D37: <meta_y_base[63:32]> | E37: 每帧配置 | F37: 压缩后 Y/RGBA metadata 存储基地址高 32 bit
A38: 3 | B38: 0x038 | C38: REG_TILE_BASE_Y_LO | D38: <tile_y_base[31:0]> | E38: 每帧配置 | F38: 压缩后 Y/RGBA tile 数据存储基地址低 32 bit
A39: 4 | B39: 0x03C | C39: REG_TILE_BASE_Y_HI | D39: <tile_y_base[63:32]> | E39: 每帧配置 | F39: 压缩后 Y/RGBA tile 数据存储基地址高 32 bit
A40: 5 | B40: 0x040 | C40: REG_META_BASE_UV_LO | D40: <meta_uv_base[31:0]> | E40: 每帧配置 | F40: UV metadata 存储基地址低 32 bit；RGBA 可写 0
A41: 6 | B41: 0x044 | C41: REG_META_BASE_UV_HI | D41: <meta_uv_base[63:32]> | E41: 每帧配置 | F41: UV metadata 存储基地址高 32 bit；RGBA 可写 0
A42: 7 | B42: 0x048 | C42: REG_TILE_BASE_UV_LO | D42: <tile_uv_base[31:0]> | E42: 每帧配置 | F42: UV tile 数据存储基地址低 32 bit；RGBA 可写 0
A43: 8 | B43: 0x04C | C43: REG_TILE_BASE_UV_HI | D43: <tile_uv_base[63:32]> | E43: 每帧配置 | F43: UV tile 数据存储基地址高 32 bit；写该 high word 后提交地址组
...

Sheet case03_2080x1800
A1: UBWC case03 寄存器配置
A2: 说明 | B2: 本页所有关键值引用总览页；如需改格式或是否使用 padding，请优先修改总览页对应行。Excel 打开后会自动重算公式。
A3: 返回总览 | B3: UBWC寄存器配置
A5: 1. 输入参数与派生尺寸
A6: 字段 | B6: 值 | C6: 说明
A7: Case ID | B7: ='UBWC寄存器配置'!A11 | C7: 原始 case 编号
A8: Use case | B8: ='UBWC寄存器配置'!B11 | C8: 原表用途
A9: 格式 | B9: ='UBWC寄存器配置'!E11 | C9: 当前配置格式；总览页可下拉修改
A10: format_code | B10: ='UBWC寄存器配置'!F11 | C10: 写入 OTF/format 字段的格式码
A11: 原图 W/H | B11: ='UBWC寄存器配置'!C11&" x "&'UBWC寄存器配置'!D11 | C11: 真实有效图像尺寸
A12: active W/H | B12: ='UBWC寄存器配置'!O11&" x "&'UBWC寄存器配置'!P11 | C12: ENC META_ACTIVE_SIZE / DEC OTF active 使用
A13: stored W/H | B13: ='UBWC寄存器配置'!Q11&" x "&'UBWC寄存器配置'!R11 | C13: UBWC layout/tile/meta 使用的对齐后尺寸
A14: ENC OTF W/H | B14: ='UBWC寄存器配置'!M11&" x "&'UBWC寄存器配置'!N11 | C14: ENC 输入流尺寸；默认不使用 padding
A15: tile W/H | B15: ='UBWC寄存器配置'!G11&" x "&'UBWC寄存器配置'!H11 | C15: 由格式决定
A16: Y tile cols/rows | B16: ='UBWC寄存器配置'!S11&" x "&'UBWC寄存器配置'!T11 | C16: Y/RGBA plane tile 数
A17: UV tile cols | B17: ='UBWC寄存器配置'!U11 | C17: RGBA 为 0；YUV420 与 Y tile cols 相同
A18: meta pitch | B18: ='UBWC寄存器配置'!V11 | C18: metadata pitch，按 64B 对齐
A19: tile pitch | B19: ='UBWC寄存器配置'!W11 | C19: 压缩 tile plane pitch 配置值
A21: 2. ENC 静态寄存器配置
A22: 步骤 | B22: 地址 | C22: 寄存器 | D22: 写入值 | E22: 配置频率 | F22: 说明
A23: 1 | B23: 0x008 | C23: REG_TILE_CFG0 | D23: ='UBWC寄存器配置'!AL11 | E23: 图像格式变化时配置 | F23: bank swizzle/bank spread 等固定建议配置
A24: 2 | B24: 0x00C | C24: REG_TILE_CFG1 | D24: ='UBWC寄存器配置'!X11 | E24: 图像格式/尺寸变化时配置 | F24: tile_pitch 和 RGBA/YUV plane 类型相关配置
A25: 3 | B25: 0x010 | C25: REG_ENC_CI_CFG0 | D25: 0x00000701 | E25: 图像格式变化时配置 | F25: CI input type=1(tiled data)，CI alen 默认 7
A26: 4 | B26: 0x020 | C26: REG_OTF_CFG0 | D26: ='UBWC寄存器配置'!Y11 | E26: 图像格式变化时配置 | F26: ENC OTF 输入 format
A27: 5 | B27: 0x024 | C27: REG_OTF_CFG1 | D27: ='UBWC寄存器配置'!Z11 | E27: 图像尺寸变化时配置 | F27: ENC OTF 输入 width/height；若总览选择 padding，则这里用 padding W/H
A28: 6 | B28: 0x028 | C28: REG_OTF_CFG2 | D28: ='UBWC寄存器配置'!AA11 | E28: 图像格式变化时配置 | F28: tile_w/tile_h
A29: 7 | B29: 0x02C | C29: REG_OTF_CFG3 | D29: ='UBWC寄存器配置'!AB11 | E29: 图像尺寸变化时配置 | F29: Y/UV tile cols；RGBA 的 UV 侧为 0
A30: 8 | B30: 0x050 | C30: REG_META_ACTIVE_SIZE | D30: ='UBWC寄存器配置'!AC11 | E30: 图像有效尺寸变化时配置 | F30: 真实 active W/H，不使用 padding W/H
A31: 9 | B31: 0x054 | C31: REG_META_PITCH | D31: ='UBWC寄存器配置'!AD11 | E31: 图像尺寸变化时配置 | F31: metadata plane pitch
A32: 10 | B32: 0x060 | C32: REG_IRQ_CTRL | D32: 0x00000001 | E32: 上电后或中断策略变化时配置 | F32: bit0 irq_enable=1；bit6 可按需配置 vsync reset enable
A34: 3. ENC 每帧地址与启动
A35: 步骤 | B35: 地址 | C35: 寄存器/字段 | D35: 写入值 | E35: 配置频率 | F35: 说明
A36: 1 | B36: 0x030 | C36: REG_META_BASE_Y_LO | D36: <meta_y_base[31:0]> | E36: 每帧配置 | F36: 压缩后 Y/RGBA metadata 存储基地址低 32 bit
A37: 2 | B37: 0x034 | C37: REG_META_BASE_Y_HI | D37: <meta_y_base[63:32]> | E37: 每帧配置 | F37: 压缩后 Y/RGBA metadata 存储基地址高 32 bit
A38: 3 | B38: 0x038 | C38: REG_TILE_BASE_Y_LO | D38: <tile_y_base[31:0]> | E38: 每帧配置 | F38: 压缩后 Y/RGBA tile 数据存储基地址低 32 bit
A39: 4 | B39: 0x03C | C39: REG_TILE_BASE_Y_HI | D39: <tile_y_base[63:32]> | E39: 每帧配置 | F39: 压缩后 Y/RGBA tile 数据存储基地址高 32 bit
A40: 5 | B40: 0x040 | C40: REG_META_BASE_UV_LO | D40: <meta_uv_base[31:0]> | E40: 每帧配置 | F40: UV metadata 存储基地址低 32 bit；RGBA 可写 0
A41: 6 | B41: 0x044 | C41: REG_META_BASE_UV_HI | D41: <meta_uv_base[63:32]> | E41: 每帧配置 | F41: UV metadata 存储基地址高 32 bit；RGBA 可写 0
A42: 7 | B42: 0x048 | C42: REG_TILE_BASE_UV_LO | D42: <tile_uv_base[31:0]> | E42: 每帧配置 | F42: UV tile 数据存储基地址低 32 bit；RGBA 可写 0
A43: 8 | B43: 0x04C | C43: REG_TILE_BASE_UV_HI | D43: <tile_uv_base[63:32]> | E43: 每帧配置 | F43: UV tile 数据存储基地址高 32 bit；写该 high word 后提交地址组
...

Sheet case04_970x2134
A1: UBWC case04 寄存器配置
A2: 说明 | B2: 本页所有关键值引用总览页；如需改格式或是否使用 padding，请优先修改总览页对应行。Excel 打开后会自动重算公式。
A3: 返回总览 | B3: UBWC寄存器配置
A5: 1. 输入参数与派生尺寸
A6: 字段 | B6: 值 | C6: 说明
A7: Case ID | B7: ='UBWC寄存器配置'!A12 | C7: 原始 case 编号
A8: Use case | B8: ='UBWC寄存器配置'!B12 | C8: 原表用途
A9: 格式 | B9: ='UBWC寄存器配置'!E12 | C9: 当前配置格式；总览页可下拉修改
A10: format_code | B10: ='UBWC寄存器配置'!F12 | C10: 写入 OTF/format 字段的格式码
A11: 原图 W/H | B11: ='UBWC寄存器配置'!C12&" x "&'UBWC寄存器配置'!D12 | C11: 真实有效图像尺寸
A12: active W/H | B12: ='UBWC寄存器配置'!O12&" x "&'UBWC寄存器配置'!P12 | C12: ENC META_ACTIVE_SIZE / DEC OTF active 使用
A13: stored W/H | B13: ='UBWC寄存器配置'!Q12&" x "&'UBWC寄存器配置'!R12 | C13: UBWC layout/tile/meta 使用的对齐后尺寸
A14: ENC OTF W/H | B14: ='UBWC寄存器配置'!M12&" x "&'UBWC寄存器配置'!N12 | C14: ENC 输入流尺寸；默认不使用 padding
A15: tile W/H | B15: ='UBWC寄存器配置'!G12&" x "&'UBWC寄存器配置'!H12 | C15: 由格式决定
A16: Y tile cols/rows | B16: ='UBWC寄存器配置'!S12&" x "&'UBWC寄存器配置'!T12 | C16: Y/RGBA plane tile 数
A17: UV tile cols | B17: ='UBWC寄存器配置'!U12 | C17: RGBA 为 0；YUV420 与 Y tile cols 相同
A18: meta pitch | B18: ='UBWC寄存器配置'!V12 | C18: metadata pitch，按 64B 对齐
A19: tile pitch | B19: ='UBWC寄存器配置'!W12 | C19: 压缩 tile plane pitch 配置值
A21: 2. ENC 静态寄存器配置
A22: 步骤 | B22: 地址 | C22: 寄存器 | D22: 写入值 | E22: 配置频率 | F22: 说明
A23: 1 | B23: 0x008 | C23: REG_TILE_CFG0 | D23: ='UBWC寄存器配置'!AL12 | E23: 图像格式变化时配置 | F23: bank swizzle/bank spread 等固定建议配置
A24: 2 | B24: 0x00C | C24: REG_TILE_CFG1 | D24: ='UBWC寄存器配置'!X12 | E24: 图像格式/尺寸变化时配置 | F24: tile_pitch 和 RGBA/YUV plane 类型相关配置
A25: 3 | B25: 0x010 | C25: REG_ENC_CI_CFG0 | D25: 0x00000701 | E25: 图像格式变化时配置 | F25: CI input type=1(tiled data)，CI alen 默认 7
A26: 4 | B26: 0x020 | C26: REG_OTF_CFG0 | D26: ='UBWC寄存器配置'!Y12 | E26: 图像格式变化时配置 | F26: ENC OTF 输入 format
A27: 5 | B27: 0x024 | C27: REG_OTF_CFG1 | D27: ='UBWC寄存器配置'!Z12 | E27: 图像尺寸变化时配置 | F27: ENC OTF 输入 width/height；若总览选择 padding，则这里用 padding W/H
A28: 6 | B28: 0x028 | C28: REG_OTF_CFG2 | D28: ='UBWC寄存器配置'!AA12 | E28: 图像格式变化时配置 | F28: tile_w/tile_h
A29: 7 | B29: 0x02C | C29: REG_OTF_CFG3 | D29: ='UBWC寄存器配置'!AB12 | E29: 图像尺寸变化时配置 | F29: Y/UV tile cols；RGBA 的 UV 侧为 0
A30: 8 | B30: 0x050 | C30: REG_META_ACTIVE_SIZE | D30: ='UBWC寄存器配置'!AC12 | E30: 图像有效尺寸变化时配置 | F30: 真实 active W/H，不使用 padding W/H
A31: 9 | B31: 0x054 | C31: REG_META_PITCH | D31: ='UBWC寄存器配置'!AD12 | E31: 图像尺寸变化时配置 | F31: metadata plane pitch
A32: 10 | B32: 0x060 | C32: REG_IRQ_CTRL | D32: 0x00000001 | E32: 上电后或中断策略变化时配置 | F32: bit0 irq_enable=1；bit6 可按需配置 vsync reset enable
A34: 3. ENC 每帧地址与启动
A35: 步骤 | B35: 地址 | C35: 寄存器/字段 | D35: 写入值 | E35: 配置频率 | F35: 说明
A36: 1 | B36: 0x030 | C36: REG_META_BASE_Y_LO | D36: <meta_y_base[31:0]> | E36: 每帧配置 | F36: 压缩后 Y/RGBA metadata 存储基地址低 32 bit
A37: 2 | B37: 0x034 | C37: REG_META_BASE_Y_HI | D37: <meta_y_base[63:32]> | E37: 每帧配置 | F37: 压缩后 Y/RGBA metadata 存储基地址高 32 bit
A38: 3 | B38: 0x038 | C38: REG_TILE_BASE_Y_LO | D38: <tile_y_base[31:0]> | E38: 每帧配置 | F38: 压缩后 Y/RGBA tile 数据存储基地址低 32 bit
A39: 4 | B39: 0x03C | C39: REG_TILE_BASE_Y_HI | D39: <tile_y_base[63:32]> | E39: 每帧配置 | F39: 压缩后 Y/RGBA tile 数据存储基地址高 32 bit
A40: 5 | B40: 0x040 | C40: REG_META_BASE_UV_LO | D40: <meta_uv_base[31:0]> | E40: 每帧配置 | F40: UV metadata 存储基地址低 32 bit；RGBA 可写 0
A41: 6 | B41: 0x044 | C41: REG_META_BASE_UV_HI | D41: <meta_uv_base[63:32]> | E41: 每帧配置 | F41: UV metadata 存储基地址高 32 bit；RGBA 可写 0
A42: 7 | B42: 0x048 | C42: REG_TILE_BASE_UV_LO | D42: <tile_uv_base[31:0]> | E42: 每帧配置 | F42: UV tile 数据存储基地址低 32 bit；RGBA 可写 0
A43: 8 | B43: 0x04C | C43: REG_TILE_BASE_UV_HI | D43: <tile_uv_base[63:32]> | E43: 每帧配置 | F43: UV tile 数据存储基地址高 32 bit；写该 high word 后提交地址组
...

Sheet case05_970x2134
A1: UBWC case05 寄存器配置
A2: 说明 | B2: 本页所有关键值引用总览页；如需改格式或是否使用 padding，请优先修改总览页对应行。Excel 打开后会自动重算公式。
A3: 返回总览 | B3: UBWC寄存器配置
A5: 1. 输入参数与派生尺寸
A6: 字段 | B6: 值 | C6: 说明
A7: Case ID | B7: ='UBWC寄存器配置'!A13 | C7: 原始 case 编号
A8: Use case | B8: ='UBWC寄存器配置'!B13 | C8: 原表用途
A9: 格式 | B9: ='UBWC寄存器配置'!E13 | C9: 当前配置格式；总览页可下拉修改
A10: format_code | B10: ='UBWC寄存器配置'!F13 | C10: 写入 OTF/format 字段的格式码
A11: 原图 W/H | B11: ='UBWC寄存器配置'!C13&" x "&'UBWC寄存器配置'!D13 | C11: 真实有效图像尺寸
A12: active W/H | B12: ='UBWC寄存器配置'!O13&" x "&'UBWC寄存器配置'!P13 | C12: ENC META_ACTIVE_SIZE / DEC OTF active 使用
A13: stored W/H | B13: ='UBWC寄存器配置'!Q13&" x "&'UBWC寄存器配置'!R13 | C13: UBWC layout/tile/meta 使用的对齐后尺寸
A14: ENC OTF W/H | B14: ='UBWC寄存器配置'!M13&" x "&'UBWC寄存器配置'!N13 | C14: ENC 输入流尺寸；默认不使用 padding
A15: tile W/H | B15: ='UBWC寄存器配置'!G13&" x "&'UBWC寄存器配置'!H13 | C15: 由格式决定
A16: Y tile cols/rows | B16: ='UBWC寄存器配置'!S13&" x "&'UBWC寄存器配置'!T13 | C16: Y/RGBA plane tile 数
A17: UV tile cols | B17: ='UBWC寄存器配置'!U13 | C17: RGBA 为 0；YUV420 与 Y tile cols 相同
A18: meta pitch | B18: ='UBWC寄存器配置'!V13 | C18: metadata pitch，按 64B 对齐
A19: tile pitch | B19: ='UBWC寄存器配置'!W13 | C19: 压缩 tile plane pitch 配置值
A21: 2. ENC 静态寄存器配置
A22: 步骤 | B22: 地址 | C22: 寄存器 | D22: 写入值 | E22: 配置频率 | F22: 说明
A23: 1 | B23: 0x008 | C23: REG_TILE_CFG0 | D23: ='UBWC寄存器配置'!AL13 | E23: 图像格式变化时配置 | F23: bank swizzle/bank spread 等固定建议配置
A24: 2 | B24: 0x00C | C24: REG_TILE_CFG1 | D24: ='UBWC寄存器配置'!X13 | E24: 图像格式/尺寸变化时配置 | F24: tile_pitch 和 RGBA/YUV plane 类型相关配置
A25: 3 | B25: 0x010 | C25: REG_ENC_CI_CFG0 | D25: 0x00000701 | E25: 图像格式变化时配置 | F25: CI input type=1(tiled data)，CI alen 默认 7
A26: 4 | B26: 0x020 | C26: REG_OTF_CFG0 | D26: ='UBWC寄存器配置'!Y13 | E26: 图像格式变化时配置 | F26: ENC OTF 输入 format
A27: 5 | B27: 0x024 | C27: REG_OTF_CFG1 | D27: ='UBWC寄存器配置'!Z13 | E27: 图像尺寸变化时配置 | F27: ENC OTF 输入 width/height；若总览选择 padding，则这里用 padding W/H
A28: 6 | B28: 0x028 | C28: REG_OTF_CFG2 | D28: ='UBWC寄存器配置'!AA13 | E28: 图像格式变化时配置 | F28: tile_w/tile_h
A29: 7 | B29: 0x02C | C29: REG_OTF_CFG3 | D29: ='UBWC寄存器配置'!AB13 | E29: 图像尺寸变化时配置 | F29: Y/UV tile cols；RGBA 的 UV 侧为 0
A30: 8 | B30: 0x050 | C30: REG_META_ACTIVE_SIZE | D30: ='UBWC寄存器配置'!AC13 | E30: 图像有效尺寸变化时配置 | F30: 真实 active W/H，不使用 padding W/H
A31: 9 | B31: 0x054 | C31: REG_META_PITCH | D31: ='UBWC寄存器配置'!AD13 | E31: 图像尺寸变化时配置 | F31: metadata plane pitch
A32: 10 | B32: 0x060 | C32: REG_IRQ_CTRL | D32: 0x00000001 | E32: 上电后或中断策略变化时配置 | F32: bit0 irq_enable=1；bit6 可按需配置 vsync reset enable
A34: 3. ENC 每帧地址与启动
A35: 步骤 | B35: 地址 | C35: 寄存器/字段 | D35: 写入值 | E35: 配置频率 | F35: 说明
A36: 1 | B36: 0x030 | C36: REG_META_BASE_Y_LO | D36: <meta_y_base[31:0]> | E36: 每帧配置 | F36: 压缩后 Y/RGBA metadata 存储基地址低 32 bit
A37: 2 | B37: 0x034 | C37: REG_META_BASE_Y_HI | D37: <meta_y_base[63:32]> | E37: 每帧配置 | F37: 压缩后 Y/RGBA metadata 存储基地址高 32 bit
A38: 3 | B38: 0x038 | C38: REG_TILE_BASE_Y_LO | D38: <tile_y_base[31:0]> | E38: 每帧配置 | F38: 压缩后 Y/RGBA tile 数据存储基地址低 32 bit
A39: 4 | B39: 0x03C | C39: REG_TILE_BASE_Y_HI | D39: <tile_y_base[63:32]> | E39: 每帧配置 | F39: 压缩后 Y/RGBA tile 数据存储基地址高 32 bit
A40: 5 | B40: 0x040 | C40: REG_META_BASE_UV_LO | D40: <meta_uv_base[31:0]> | E40: 每帧配置 | F40: UV metadata 存储基地址低 32 bit；RGBA 可写 0
A41: 6 | B41: 0x044 | C41: REG_META_BASE_UV_HI | D41: <meta_uv_base[63:32]> | E41: 每帧配置 | F41: UV metadata 存储基地址高 32 bit；RGBA 可写 0
A42: 7 | B42: 0x048 | C42: REG_TILE_BASE_UV_LO | D42: <tile_uv_base[31:0]> | E42: 每帧配置 | F42: UV tile 数据存储基地址低 32 bit；RGBA 可写 0
A43: 8 | B43: 0x04C | C43: REG_TILE_BASE_UV_HI | D43: <tile_uv_base[63:32]> | E43: 每帧配置 | F43: UV tile 数据存储基地址高 32 bit；写该 high word 后提交地址组
...
